// using System;

// namespace Exception_example
// {
//     class Program
//     {
//         static void Main(string[] args)
//         {


//             int ticketNo;
//             try{
//                 System.Console.WriteLine("Enter ticket no :- ");
//                 ticketNo=Convert.ToInt32(Console.ReadLine());
//                 if(ticketNo>50)
//                 {
//                     throw new CustomException("Ticket no not avalible ");
//                 }
//                 System.Console.WriteLine("Your ticket has been booked successfully ");
//             }
//             catch(CustomException e)
//             {
//                 System.Console.WriteLine(e.Message);

//             }


  

























//             // int a, b, c;

//             // try
//             // {


//             //     System.Console.WriteLine("Enter a no");
//             //     a = Convert.ToInt32(Console.ReadLine());
//             //     System.Console.WriteLine("Enter b no ");
//             //     b = Convert.ToInt32(Console.ReadLine());

//             //     c = a / b;
//             //     System.Console.WriteLine($"{a}/{b}={c}");

//             // }


//             // catch (Exception e)
//             // {
//             //     System.Console.WriteLine("e message " + e.Message);
//             //     System.Console.WriteLine("source name is :- " + e.Source);
//             //     System.Console.WriteLine("Stack Trace" + e.StackTrace);
//             //     System.Console.WriteLine("Help LInk" + e.HelpLink);
//             //     System.Console.WriteLine("Target sits" + e.TargetSite);
//             // }

//             // finally
//             // {
//             //     System.Console.WriteLine("Pj pj ");
//             // }



//             // write three static function which are void method f1 will call f2 f2 will call f3 and f3 have code.
//             // in main function call f1 only. use try catch.


//         }
//     }
// }
